Workbook
Name Nper: Parameters!$K$4
Name Percentages: Parameters!$K$8
Name Start_Date: Parameters!$K$6
Name Type: Parameters!$K$5
Name PV: ASTemp!$E$4
Name Decimals: Parameters!$K$7
Name PV: 'Amortization Schedule'!$E$4
Name Rate: Parameters!$K$3

Sheet Amortization Schedule
O1: =""
B2: ="Loan Payment Schedule for "&$L$4&" "&$L$5 -> Loan Payment Schedule for Mr. Eddie Kouton
B4: Loan Amount | E4: 500000 | J4: Salution | L4: Mr.
B5: Interest Rate | E5: 0.05 | F5: Yearly | J5: Borrower's Name | L5: Eddie Kouton
B6: Loan Period | E6: 12 | F6: Months | J6: Lender's Name | L6: Citi Bank
B7: Payment Frequency | E7: Weekly | J7: Date Loan Taken | L7: 42087
B8: Start Year & Month of Payment | E8: 2015 | F8: Sep | J8: Total Interest Paid | L8: =TEXT(ASTemp!L8,Decimals) -> 12844.5
B9: No. of Decimal Places in Figures | E9: 1 | J9: Total Amount Paid | L9: =TEXT(ASTemp!L9,Decimals) -> 512844.5
B10: EMI Due - Start / End of the Period
B12: Payment No. | C12: Date of Payment | D12: Year | E12: Month | F12: Starting Balance | G12: Payment | H12: Principal Payment | I12: Interest Payment | J12: Cumulative Principal | K12: Cumulative Interest | L12: Loan Remaining | M12: % of Loan Paid Up | N12: % of Loan Remaining
B13: =ASTemp!B13 -> 1 | C13: =ASTemp!C13 -> 42277 | D13: =ASTemp!D13 -> 2015 | E13: =ASTemp!E13 -> Sep | F13: =TEXT(ASTemp!F13,Decimals) -> 500000.0 | G13: =TEXT(ASTemp!G13,Decimals) -> 9862.4 | H13: =TEXT(ASTemp!H13,Decimals) -> 9381.6 | I13: =TEXT(ASTemp!I13,Decimals) -> 480.8 | J13: =TEXT(ASTemp!J13,Decimals) -> 9381.6 | K13: =TEXT(ASTemp!K13,Decimals) -> 480.8 | L13: =TEXT(ASTemp!L13,Decimals) -> 490618.4 | M13: =TEXT(ASTemp!M13,Percentages) -> 1.9% | N13: =TEXT(ASTemp!N13,Percentages) -> 98.1%
B14: =ASTemp!B14 -> 2 | C14: =ASTemp!C14 -> 42284 | D14: =ASTemp!D14 -> 2015 | E14: =ASTemp!E14 -> Oct | F14: =TEXT(ASTemp!F14,Decimals) -> 490618.4 | G14: =TEXT(ASTemp!G14,Decimals) -> 9862.4 | H14: =TEXT(ASTemp!H14,Decimals) -> 9390.6 | I14: =TEXT(ASTemp!I14,Decimals) -> 471.7 | J14: =TEXT(ASTemp!J14,Decimals) -> 18772.3 | K14: =TEXT(ASTemp!K14,Decimals) -> 952.5 | L14: =TEXT(ASTemp!L14,Decimals) -> 481227.7 | M14: =TEXT(ASTemp!M14,Percentages) -> 3.8% | N14: =TEXT(ASTemp!N14,Percentages) -> 96.2%
B15: =ASTemp!B15 -> 3 | C15: =ASTemp!C15 -> 42291 | D15: =ASTemp!D15 -> 2015 | E15: =ASTemp!E15 -> Oct | F15: =TEXT(ASTemp!F15,Decimals) -> 481227.7 | G15: =TEXT(ASTemp!G15,Decimals) -> 9862.4 | H15: =TEXT(ASTemp!H15,Decimals) -> 9399.7 | I15: =TEXT(ASTemp!I15,Decimals) -> 462.7 | J15: =TEXT(ASTemp!J15,Decimals) -> 28171.9 | K15: =TEXT(ASTemp!K15,Decimals) -> 1415.2 | L15: =TEXT(ASTemp!L15,Decimals) -> 471828.1 | M15: =TEXT(ASTemp!M15,Percentages) -> 5.6% | N15: =TEXT(ASTemp!N15,Percentages) -> 94.4%
B16: =ASTemp!B16 -> 4 | C16: =ASTemp!C16 -> 42298 | D16: =ASTemp!D16 -> 2015 | E16: =ASTemp!E16 -> Oct | F16: =TEXT(ASTemp!F16,Decimals) -> 471828.1 | G16: =TEXT(ASTemp!G16,Decimals) -> 9862.4 | H16: =TEXT(ASTemp!H16,Decimals) -> 9408.7 | I16: =TEXT(ASTemp!I16,Decimals) -> 453.7 | J16: =TEXT(ASTemp!J16,Decimals) -> 37580.7 | K16: =TEXT(ASTemp!K16,Decimals) -> 1868.9 | L16: =TEXT(ASTemp!L16,Decimals) -> 462419.3 | M16: =TEXT(ASTemp!M16,Percentages) -> 7.5% | N16: =TEXT(ASTemp!N16,Percentages) -> 92.5%
B17: =ASTemp!B17 -> 5 | C17: =ASTemp!C17 -> 42305 | D17: =ASTemp!D17 -> 2015 | E17: =ASTemp!E17 -> Oct | F17: =TEXT(ASTemp!F17,Decimals) -> 462419.3 | G17: =TEXT(ASTemp!G17,Decimals) -> 9862.4 | H17: =TEXT(ASTemp!H17,Decimals) -> 9417.8 | I17: =TEXT(ASTemp!I17,Decimals) -> 444.6 | J17: =TEXT(ASTemp!J17,Decimals) -> 46998.4 | K17: =TEXT(ASTemp!K17,Decimals) -> 2313.6 | L17: =TEXT(ASTemp!L17,Decimals) -> 453001.6 | M17: =TEXT(ASTemp!M17,Percentages) -> 9.4% | N17: =TEXT(ASTemp!N17,Percentages) -> 90.6%
B18: =ASTemp!B18 -> 6 | C18: =ASTemp!C18 -> 42312 | D18: =ASTemp!D18 -> 2015 | E18: =ASTemp!E18 -> Nov | F18: =TEXT(ASTemp!F18,Decimals) -> 453001.6 | G18: =TEXT(ASTemp!G18,Decimals) -> 9862.4 | H18: =TEXT(ASTemp!H18,Decimals) -> 9426.8 | I18: =TEXT(ASTemp!I18,Decimals) -> 435.6 | J18: =TEXT(ASTemp!J18,Decimals) -> 56425.2 | K18: =TEXT(ASTemp!K18,Decimals) -> 2749.1 | L18: =TEXT(ASTemp!L18,Decimals) -> 443574.8 | M18: =TEXT(ASTemp!M18,Percentages) -> 11.3% | N18: =TEXT(ASTemp!N18,Percentages) -> 88.7%
B19: =ASTemp!B19 -> 7 | C19: =ASTemp!C19 -> 42319 | D19: =ASTemp!D19 -> 2015 | E19: =ASTemp!E19 -> Nov | F19: =TEXT(ASTemp!F19,Decimals) -> 443574.8 | G19: =TEXT(ASTemp!G19,Decimals) -> 9862.4 | H19: =TEXT(ASTemp!H19,Decimals) -> 9435.9 | I19: =TEXT(ASTemp!I19,Decimals) -> 426.5 | J19: =TEXT(ASTemp!J19,Decimals) -> 65861.1 | K19: =TEXT(ASTemp!K19,Decimals) -> 3175.6 | L19: =TEXT(ASTemp!L19,Decimals) -> 434138.9 | M19: =TEXT(ASTemp!M19,Percentages) -> 13.2% | N19: =TEXT(ASTemp!N19,Percentages) -> 86.8%
B20: =ASTemp!B20 -> 8 | C20: =ASTemp!C20 -> 42326 | D20: =ASTemp!D20 -> 2015 | E20: =ASTemp!E20 -> Nov | F20: =TEXT(ASTemp!F20,Decimals) -> 434138.9 | G20: =TEXT(ASTemp!G20,Decimals) -> 9862.4 | H20: =TEXT(ASTemp!H20,Decimals) -> 9445.0 | I20: =TEXT(ASTemp!I20,Decimals) -> 417.4 | J20: =TEXT(ASTemp!J20,Decimals) -> 75306.1 | K20: =TEXT(ASTemp!K20,Decimals) -> 3593.1 | L20: =TEXT(ASTemp!L20,Decimals) -> 424693.9 | M20: =TEXT(ASTemp!M20,Percentages) -> 15.1% | N20: =TEXT(ASTemp!N20,Percentages) -> 84.9%
B21: =ASTemp!B21 -> 9 | C21: =ASTemp!C21 -> 42333 | D21: =ASTemp!D21 -> 2015 | E21: =ASTemp!E21 -> Nov | F21: =TEXT(ASTemp!F21,Decimals) -> 424693.9 | G21: =TEXT(ASTemp!G21,Decimals) -> 9862.4 | H21: =TEXT(ASTemp!H21,Decimals) -> 9454.0 | I21: =TEXT(ASTemp!I21,Decimals) -> 408.4 | J21: =TEXT(ASTemp!J21,Decimals) -> 84760.1 | K21: =TEXT(ASTemp!K21,Decimals) -> 4001.4 | L21: =TEXT(ASTemp!L21,Decimals) -> 415239.9 | M21: =TEXT(ASTemp!M21,Percentages) -> 17.0% | N21: =TEXT(ASTemp!N21,Percentages) -> 83.0%
B22: =ASTemp!B22 -> 10 | C22: =ASTemp!C22 -> 42340 | D22: =ASTemp!D22 -> 2015 | E22: =ASTemp!E22 -> Dec | F22: =TEXT(ASTemp!F22,Decimals) -> 415239.9 | G22: =TEXT(ASTemp!G22,Decimals) -> 9862.4 | H22: =TEXT(ASTemp!H22,Decimals) -> 9463.1 | I22: =TEXT(ASTemp!I22,Decimals) -> 399.3 | J22: =TEXT(ASTemp!J22,Decimals) -> 94223.2 | K22: =TEXT(ASTemp!K22,Decimals) -> 4400.7 | L22: =TEXT(ASTemp!L22,Decimals) -> 405776.8 | M22: =TEXT(ASTemp!M22,Percentages) -> 18.8% | N22: =TEXT(ASTemp!N22,Percentages) -> 81.2%
B23: =ASTemp!B23 -> 11 | C23: =ASTemp!C23 -> 42347 | D23: =ASTemp!D23 -> 2015 | E23: =ASTemp!E23 -> Dec | F23: =TEXT(ASTemp!F23,Decimals) -> 405776.8 | G23: =TEXT(ASTemp!G23,Decimals) -> 9862.4 | H23: =TEXT(ASTemp!H23,Decimals) -> 9472.2 | I23: =TEXT(ASTemp!I23,Decimals) -> 390.2 | J23: =TEXT(ASTemp!J23,Decimals) -> 103695.4 | K23: =TEXT(ASTemp!K23,Decimals) -> 4790.9 | L23: =TEXT(ASTemp!L23,Decimals) -> 396304.6 | M23: =TEXT(ASTemp!M23,Percentages) -> 20.7% | N23: =TEXT(ASTemp!N23,Percentages) -> 79.3%
B24: =ASTemp!B24 -> 12 | C24: =ASTemp!C24 -> 42354 | D24: =ASTemp!D24 -> 2015 | E24: =ASTemp!E24 -> Dec | F24: =TEXT(ASTemp!F24,Decimals) -> 396304.6 | G24: =TEXT(ASTemp!G24,Decimals) -> 9862.4 | H24: =TEXT(ASTemp!H24,Decimals) -> 9481.3 | I24: =TEXT(ASTemp!I24,Decimals) -> 381.1 | J24: =TEXT(ASTemp!J24,Decimals) -> 113176.8 | K24: =TEXT(ASTemp!K24,Decimals) -> 5171.9 | L24: =TEXT(ASTemp!L24,Decimals) -> 386823.2 | M24: =TEXT(ASTemp!M24,Percentages) -> 22.6% | N24: =TEXT(ASTemp!N24,Percentages) -> 77.4%
... B2611: =ASTemp!B2611 | C2611: =ASTemp!C2611 | D2611: =ASTemp!D2611 | E2611: =ASTemp!E2611 | F2611: =TEXT(ASTemp!F2611,Decimals) | G2611: =TEXT(ASTemp!G2611,Decimals) | H2611: =TEXT(ASTemp!H2611,Decimals) | I2611: =TEXT(ASTemp!I2611,Decimals) | J2611: =TEXT(ASTemp!J2611,Decimals) | K2611: =TEXT(ASTemp!K2611,Decimals) | L2611: =TEXT(ASTemp!L2611,Decimals) | M2611: =TEXT(ASTemp!M2611,Percentages) | N2611: =TEXT(ASTemp!N2611,Percentages)

Sheet ASTemp
O1: =""
B2: ="Loan Payment Schedule for "&$L$4&" "&$L$5 -> Loan Payment Schedule for Mr. Eddie Kouton
B4: Loan Amount | E4: ='Amortization Schedule'!PV -> 500000 | J4: Salution | L4: ='Amortization Schedule'!L4:N4 -> Mr.
B5: Interest Rate | E5: ='Amortization Schedule'!E5 -> 0.05 | F5: =IF('Amortization Schedule'!F5="","",'Amortization Schedule'!F5) -> Yearly | J5: Borrower's Name | L5: ='Amortization Schedule'!L5:N5 -> Eddie Kouton
B6: Loan Period | E6: ='Amortization Schedule'!E6 -> 12 | F6: =IF('Amortization Schedule'!F6="","",'Amortization Schedule'!F6) -> Months | J6: Lender's Name | L6: ='Amortization Schedule'!L6:N6 -> Citi Bank
B7: Payment Frequency | E7: =IF('Amortization Schedule'!E7="","",'Amortization Schedule'!E7) -> Weekly | J7: Date Loan Taken | L7: ='Amortization Schedule'!L7:N7 -> 42087
B8: Start Year & Month of Payment | E8: ='Amortization Schedule'!E8 -> 2015 | F8: ='Amortization Schedule'!F8 -> Sep | J8: Total Interest Paid | L8: =SUM($I$13:$I$2611) -> 12844.458
B9: No. of Decimal Places in Figures | E9: ='Amortization Schedule'!E9:F9 -> 1 | J9: Total Amount Paid | L9: =SUM($G$13:$G$2611) -> 512844.46
B10: EMI Due - Start / End of the Period
B12: Payment No. | C12: Date of Payment | D12: Year | E12: Month | F12: Starting Balance | G12: Payment | H12: Principal Payment | I12: Interest Payment | J12: Cumulative Principal | K12: Cumulative Interest | L12: Loan Remaining | M12: % of Loan Paid Up | N12: % of Loan Remaining
B13: =IF(ROWS($1:1)<=Nper,ROWS($1:1),"") -> 1 | C13: =IF($B13="","",IF($E$7="Weekly",Start_Date+7*(ROWS($1:1)-1),EDATE(Start_Date,VLOOKUP(IF(ASTemp!$E$7="","Monthly",ASTemp!$E$7),Parameters!$B$3:$D$6,3,0)*(ROWS($1:1)-1)))) -> 42277 | D13: =IF($B13="","",YEAR(C13)) -> 2015 | E13: =IF($B13="","",VLOOKUP(MONTH(C13),Parameters!$F$2:$G$13,2,0)) -> Sep | F13: =IF($B13="","",PV-N(J12)) -> 500000 | G13: =IF($B13="","",PMT(Rate,Nper,-PV,,Type)) -> 9862.3934 | H13: =IF($B13="","",PPMT(Rate,ROWS($1:1),Nper,-PV,,Type)) -> 9381.6242 | I13: =IF($B13="","",IPMT(Rate,ROWS($1:1),Nper,-PV,,Type)) -> 480.76923 | J13: =IF($B13="","",N(J12)+N(H13)) -> 9381.6242 | K13: =IF($B13="","",N(K12)+N(I13)) -> 480.76923 | L13: =IF($B13="","",PV-J13) -> 490618.38 | M13: =IF($B13="","",J13/PV) -> 0.018763248 | N13: =IF($B13="","",1-M13) -> 0.98123675
B14: =IF(ROWS($1:2)<=Nper,ROWS($1:2),"") -> 2 | C14: =IF($B14="","",IF($E$7="Weekly",Start_Date+7*(ROWS($1:2)-1),EDATE(Start_Date,VLOOKUP(IF(ASTemp!$E$7="","Monthly",ASTemp!$E$7),Parameters!$B$3:$D$6,3,0)*(ROWS($1:2)-1)))) -> 42284 | D14: =IF($B14="","",YEAR(C14)) -> 2015 | E14: =IF($B14="","",VLOOKUP(MONTH(C14),Parameters!$F$2:$G$13,2,0)) -> Oct | F14: =IF($B14="","",PV-N(J13)) -> 490618.38 | G14: =IF($B14="","",PMT(Rate,Nper,-PV,,Type)) -> 9862.3934 | H14: =IF($B14="","",PPMT(Rate,ROWS($1:2),Nper,-PV,,Type)) -> 9390.645 | I14: =IF($B14="","",IPMT(Rate,ROWS($1:2),Nper,-PV,,Type)) -> 471.74844 | J14: =IF($B14="","",N(J13)+N(H14)) -> 18772.269 | K14: =IF($B14="","",N(K13)+N(I14)) -> 952.51767 | L14: =IF($B14="","",PV-J14) -> 481227.73 | M14: =IF($B14="","",J14/PV) -> 0.037544538 | N14: =IF($B14="","",1-M14) -> 0.96245546
B15: =IF(ROWS($1:3)<=Nper,ROWS($1:3),"") -> 3 | C15: =IF($B15="","",IF($E$7="Weekly",Start_Date+7*(ROWS($1:3)-1),EDATE(Start_Date,VLOOKUP(IF(ASTemp!$E$7="","Monthly",ASTemp!$E$7),Parameters!$B$3:$D$6,3,0)*(ROWS($1:3)-1)))) -> 42291 | D15: =IF($B15="","",YEAR(C15)) -> 2015 | E15: =IF($B15="","",VLOOKUP(MONTH(C15),Parameters!$F$2:$G$13,2,0)) -> Oct | F15: =IF($B15="","",PV-N(J14)) -> 481227.73 | G15: =IF($B15="","",PMT(Rate,Nper,-PV,,Type)) -> 9862.3934 | H15: =IF($B15="","",PPMT(Rate,ROWS($1:3),Nper,-PV,,Type)) -> 9399.6745 | I15: =IF($B15="","",IPMT(Rate,ROWS($1:3),Nper,-PV,,Type)) -> 462.71897 | J15: =IF($B15="","",N(J14)+N(H15)) -> 28171.944 | K15: =IF($B15="","",N(K14)+N(I15)) -> 1415.2366 | L15: =IF($B15="","",PV-J15) -> 471828.06 | M15: =IF($B15="","",J15/PV) -> 0.056343887 | N15: =IF($B15="","",1-M15) -> 0.94365611
B16: =IF(ROWS($1:4)<=Nper,ROWS($1:4),"") -> 4 | C16: =IF($B16="","",IF($E$7="Weekly",Start_Date+7*(ROWS($1:4)-1),EDATE(Start_Date,VLOOKUP(IF(ASTemp!$E$7="","Monthly",ASTemp!$E$7),Parameters!$B$3:$D$6,3,0)*(ROWS($1:4)-1)))) -> 42298 | D16: =IF($B16="","",YEAR(C16)) -> 2015 | E16: =IF($B16="","",VLOOKUP(MONTH(C16),Parameters!$F$2:$G$13,2,0)) -> Oct | F16: =IF($B16="","",PV-N(J15)) -> 471828.06 | G16: =IF($B16="","",PMT(Rate,Nper,-PV,,Type)) -> 9862.3934 | H16: =IF($B16="","",PPMT(Rate,ROWS($1:4),Nper,-PV,,Type)) -> 9408.7126 | I16: =IF($B16="","",IPMT(Rate,ROWS($1:4),Nper,-PV,,Type)) -> 453.68082 | J16: =IF($B16="","",N(J15)+N(H16)) -> 37580.656 | K16: =IF($B16="","",N(K15)+N(I16)) -> 1868.9175 | L16: =IF($B16="","",PV-J16) -> 462419.34 | M16: =IF($B16="","",J16/PV) -> 0.075161313 | N16: =IF($B16="","",1-M16) -> 0.92483869
B17: =IF(ROWS($1:5)<=Nper,ROWS($1:5),"") -> 5 | C17: =IF($B17="","",IF($E$7="Weekly",Start_Date+7*(ROWS($1:5)-1),EDATE(Start_Date,VLOOKUP(IF(ASTemp!$E$7="","Monthly",ASTemp!$E$7),Parameters!$B$3:$D$6,3,0)*(ROWS($1:5)-1)))) -> 42305 | D17: =IF($B17="","",YEAR(C17)) -> 2015 | E17: =IF($B17="","",VLOOKUP(MONTH(C17),Parameters!$F$2:$G$13,2,0)) -> Oct | F17: =IF($B17="","",PV-N(J16)) -> 462419.34 | G17: =IF($B17="","",PMT(Rate,Nper,-PV,,Type)) -> 9862.3934 | H17: =IF($B17="","",PPMT(Rate,ROWS($1:5),Nper,-PV,,Type)) -> 9417.7594 | I17: =IF($B17="","",IPMT(Rate,ROWS($1:5),Nper,-PV,,Type)) -> 444.63398 | J17: =IF($B17="","",N(J16)+N(H17)) -> 46998.416 | K17: =IF($B17="","",N(K16)+N(I17)) -> 2313.5514 | L17: =IF($B17="","",PV-J17) -> 453001.58 | M17: =IF($B17="","",J17/PV) -> 0.093996831 | N17: =IF($B17="","",1-M17) -> 0.90600317
B18: =IF(ROWS($1:6)<=Nper,ROWS($1:6),"") -> 6 | C18: =IF($B18="","",IF($E$7="Weekly",Start_Date+7*(ROWS($1:6)-1),EDATE(Start_Date,VLOOKUP(IF(ASTemp!$E$7="","Monthly",ASTemp!$E$7),Parameters!$B$3:$D$6,3,0)*(ROWS($1:6)-1)))) -> 42312 | D18: =IF($B18="","",YEAR(C18)) -> 2015 | E18: =IF($B18="","",VLOOKUP(MONTH(C18),Parameters!$F$2:$G$13,2,0)) -> Nov | F18: =IF($B18="","",PV-N(J17)) -> 453001.58 | G18: =IF($B18="","",PMT(Rate,Nper,-PV,,Type)) -> 9862.3934 | H18: =IF($B18="","",PPMT(Rate,ROWS($1:6),Nper,-PV,,Type)) -> 9426.815 | I18: =IF($B18="","",IPMT(Rate,ROWS($1:6),Nper,-PV,,Type)) -> 435.57845 | J18: =IF($B18="","",N(J17)+N(H18)) -> 56425.231 | K18: =IF($B18="","",N(K17)+N(I18)) -> 2749.1299 | L18: =IF($B18="","",PV-J18) -> 443574.77 | M18: =IF($B18="","",J18/PV) -> 0.11285046 | N18: =IF($B18="","",1-M18) -> 0.88714954
B19: =IF(ROWS($1:7)<=Nper,ROWS($1:7),"") -> 7 | C19: =IF($B19="","",IF($E$7="Weekly",Start_Date+7*(ROWS($1:7)-1),EDATE(Start_Date,VLOOKUP(IF(ASTemp!$E$7="","Monthly",ASTemp!$E$7),Parameters!$B$3:$D$6,3,0)*(ROWS($1:7)-1)))) -> 42319 | D19: =IF($B19="","",YEAR(C19)) -> 2015 | E19: =IF($B19="","",VLOOKUP(MONTH(C19),Parameters!$F$2:$G$13,2,0)) -> Nov | F19: =IF($B19="","",PV-N(J18)) -> 443574.77 | G19: =IF($B19="","",PMT(Rate,Nper,-PV,,Type)) -> 9862.3934 | H19: =IF($B19="","",PPMT(Rate,ROWS($1:7),Nper,-PV,,Type)) -> 9435.8792 | I19: =IF($B19="","",IPMT(Rate,ROWS($1:7),Nper,-PV,,Type)) -> 426.5142 | J19: =IF($B19="","",N(J18)+N(H19)) -> 65861.11 | K19: =IF($B19="","",N(K18)+N(I19)) -> 3175.6441 | L19: =IF($B19="","",PV-J19) -> 434138.89 | M19: =IF($B19="","",J19/PV) -> 0.13172222 | N19: =IF($B19="","",1-M19) -> 0.86827778
B20: =IF(ROWS($1:8)<=Nper,ROWS($1:8),"") -> 8 | C20: =IF($B20="","",IF($E$7="Weekly",Start_Date+7*(ROWS($1:8)-1),EDATE(Start_Date,VLOOKUP(IF(ASTemp!$E$7="","Monthly",ASTemp!$E$7),Parameters!$B$3:$D$6,3,0)*(ROWS($1:8)-1)))) -> 42326 | D20: =IF($B20="","",YEAR(C20)) -> 2015 | E20: =IF($B20="","",VLOOKUP(MONTH(C20),Parameters!$F$2:$G$13,2,0)) -> Nov | F20: =IF($B20="","",PV-N(J19)) -> 434138.89 | G20: =IF($B20="","",PMT(Rate,Nper,-PV,,Type)) -> 9862.3934 | H20: =IF($B20="","",PPMT(Rate,ROWS($1:8),Nper,-PV,,Type)) -> 9444.9522 | I20: =IF($B20="","",IPMT(Rate,ROWS($1:8),Nper,-PV,,Type)) -> 417.44124 | J20: =IF($B20="","",N(J19)+N(H20)) -> 75306.062 | K20: =IF($B20="","",N(K19)+N(I20)) -> 3593.0853 | L20: =IF($B20="","",PV-J20) -> 424693.94 | M20: =IF($B20="","",J20/PV) -> 0.15061212 | N20: =IF($B20="","",1-M20) -> 0.84938788
B21: =IF(ROWS($1:9)<=Nper,ROWS($1:9),"") -> 9 | C21: =IF($B21="","",IF($E$7="Weekly",Start_Date+7*(ROWS($1:9)-1),EDATE(Start_Date,VLOOKUP(IF(ASTemp!$E$7="","Monthly",ASTemp!$E$7),Parameters!$B$3:$D$6,3,0)*(ROWS($1:9)-1)))) -> 42333 | D21: =IF($B21="","",YEAR(C21)) -> 2015 | E21: =IF($B21="","",VLOOKUP(MONTH(C21),Parameters!$F$2:$G$13,2,0)) -> Nov | F21: =IF($B21="","",PV-N(J20)) -> 424693.94 | G21: =IF($B21="","",PMT(Rate,Nper,-PV,,Type)) -> 9862.3934 | H21: =IF($B21="","",PPMT(Rate,ROWS($1:9),Nper,-PV,,Type)) -> 9454.0339 | I21: =IF($B21="","",IPMT(Rate,ROWS($1:9),Nper,-PV,,Type)) -> 408.35956 | J21: =IF($B21="","",N(J20)+N(H21)) -> 84760.096 | K21: =IF($B21="","",N(K20)+N(I21)) -> 4001.4449 | L21: =IF($B21="","",PV-J21) -> 415239.9 | M21: =IF($B21="","",J21/PV) -> 0.16952019 | N21: =IF($B21="","",1-M21) -> 0.83047981
B22: =IF(ROWS($1:10)<=Nper,ROWS($1:10),"") -> 10 | C22: =IF($B22="","",IF($E$7="Weekly",Start_Date+7*(ROWS($1:10)-1),EDATE(Start_Date,VLOOKUP(IF(ASTemp!$E$7="","Monthly",ASTemp!$E$7),Parameters!$B$3:$D$6,3,0)*(ROWS($1:10)-1)))) -> 42340 | D22: =IF($B22="","",YEAR(C22)) -> 2015 | E22: =IF($B22="","",VLOOKUP(MONTH(C22),Parameters!$F$2:$G$13,2,0)) -> Dec | F22: =IF($B22="","",PV-N(J21)) -> 415239.9 | G22: =IF($B22="","",PMT(Rate,Nper,-PV,,Type)) -> 9862.3934 | H22: =IF($B22="","",PPMT(Rate,ROWS($1:10),Nper,-PV,,Type)) -> 9463.1243 | I22: =IF($B22="","",IPMT(Rate,ROWS($1:10),Nper,-PV,,Type)) -> 399.26914 | J22: =IF($B22="","",N(J21)+N(H22)) -> 94223.22 | K22: =IF($B22="","",N(K21)+N(I22)) -> 4400.714 | L22: =IF($B22="","",PV-J22) -> 405776.78 | M22: =IF($B22="","",J22/PV) -> 0.18844644 | N22: =IF($B22="","",1-M22) -> 0.81155356
B23: =IF(ROWS($1:11)<=Nper,ROWS($1:11),"") -> 11 | C23: =IF($B23="","",IF($E$7="Weekly",Start_Date+7*(ROWS($1:11)-1),EDATE(Start_Date,VLOOKUP(IF(ASTemp!$E$7="","Monthly",ASTemp!$E$7),Parameters!$B$3:$D$6,3,0)*(ROWS($1:11)-1)))) -> 42347 | D23: =IF($B23="","",YEAR(C23)) -> 2015 | E23: =IF($B23="","",VLOOKUP(MONTH(C23),Parameters!$F$2:$G$13,2,0)) -> Dec | F23: =IF($B23="","",PV-N(J22)) -> 405776.78 | G23: =IF($B23="","",PMT(Rate,Nper,-PV,,Type)) -> 9862.3934 | H23: =IF($B23="","",PPMT(Rate,ROWS($1:11),Nper,-PV,,Type)) -> 9472.2234 | I23: =IF($B23="","",IPMT(Rate,ROWS($1:11),Nper,-PV,,Type)) -> 390.16998 | J23: =IF($B23="","",N(J22)+N(H23)) -> 103695.44 | K23: =IF($B23="","",N(K22)+N(I23)) -> 4790.884 | L23: =IF($B23="","",PV-J23) -> 396304.56 | M23: =IF($B23="","",J23/PV) -> 0.20739089 | N23: =IF($B23="","",1-M23) -> 0.79260911
B24: =IF(ROWS($1:12)<=Nper,ROWS($1:12),"") -> 12 | C24: =IF($B24="","",IF($E$7="Weekly",Start_Date+7*(ROWS($1:12)-1),EDATE(Start_Date,VLOOKUP(IF(ASTemp!$E$7="","Monthly",ASTemp!$E$7),Parameters!$B$3:$D$6,3,0)*(ROWS($1:12)-1)))) -> 42354 | D24: =IF($B24="","",YEAR(C24)) -> 2015 | E24: =IF($B24="","",VLOOKUP(MONTH(C24),Parameters!$F$2:$G$13,2,0)) -> Dec | F24: =IF($B24="","",PV-N(J23)) -> 396304.56 | G24: =IF($B24="","",PMT(Rate,Nper,-PV,,Type)) -> 9862.3934 | H24: =IF($B24="","",PPMT(Rate,ROWS($1:12),Nper,-PV,,Type)) -> 9481.3314 | I24: =IF($B24="","",IPMT(Rate,ROWS($1:12),Nper,-PV,,Type)) -> 381.06207 | J24: =IF($B24="","",N(J23)+N(H24)) -> 113176.78 | K24: =IF($B24="","",N(K23)+N(I24)) -> 5171.9461 | L24: =IF($B24="","",PV-J24) -> 386823.22 | M24: =IF($B24="","",J24/PV) -> 0.22635355 | N24: =IF($B24="","",1-M24) -> 0.77364645
B25: =IF(ROWS($1:13)<=Nper,ROWS($1:13),"") -> 13 | C25: =IF($B25="","",IF($E$7="Weekly",Start_Date+7*(ROWS($1:13)-1),EDATE(Start_Date,VLOOKUP(IF(ASTemp!$E$7="","Monthly",ASTemp!$E$7),Parameters!$B$3:$D$6,3,0)*(ROWS($1:13)-1)))) -> 42361 | D25: =IF($B25="","",YEAR(C25)) -> 2015 | E25: =IF($B25="","",VLOOKUP(MONTH(C25),Parameters!$F$2:$G$13,2,0)) -> Dec | F25: =IF($B25="","",PV-N(J24)) -> 386823.22 | G25: =IF($B25="","",PMT(Rate,Nper,-PV,,Type)) -> 9862.3934 | H25: =IF($B25="","",PPMT(Rate,ROWS($1:13),Nper,-PV,,Type)) -> 9490.448 | I25: =IF($B25="","",IPMT(Rate,ROWS($1:13),Nper,-PV,,Type)) -> 371.94541 | J25: =IF($B25="","",N(J24)+N(H25)) -> 122667.22 | K25: =IF($B25="","",N(K24)+N(I25)) -> 5543.8915 | L25: =IF($B25="","",PV-J25) -> 377332.78 | M25: =IF($B25="","",J25/PV) -> 0.24533445 | N25: =IF($B25="","",1-M25) -> 0.75466555
B26: =IF(ROWS($1:14)<=Nper,ROWS($1:14),"") -> 14 | C26: =IF($B26="","",IF($E$7="Weekly",Start_Date+7*(ROWS($1:14)-1),EDATE(Start_Date,VLOOKUP(IF(ASTemp!$E$7="","Monthly",ASTemp!$E$7),Parameters!$B$3:$D$6,3,0)*(ROWS($1:14)-1)))) -> 42368 | D26: =IF($B26="","",YEAR(C26)) -> 2015 | E26: =IF($B26="","",VLOOKUP(MONTH(C26),Parameters!$F$2:$G$13,2,0)) -> Dec | F26: =IF($B26="","",PV-N(J25)) -> 377332.78 | G26: =IF($B26="","",PMT(Rate,Nper,-PV,,Type)) -> 9862.3934 | H26: =IF($B26="","",PPMT(Rate,ROWS($1:14),Nper,-PV,,Type)) -> 9499.5735 | I26: =IF($B26="","",IPMT(Rate,ROWS($1:14),Nper,-PV,,Type)) -> 362.81998 | J26: =IF($B26="","",N(J25)+N(H26)) -> 132166.8 | K26: =IF($B26="","",N(K25)+N(I26)) -> 5906.7115 | L26: =IF($B26="","",PV-J26) -> 367833.2 | M26: =IF($B26="","",J26/PV) -> 0.26433359 | N26: =IF($B26="","",1-M26) -> 0.73566641
B27: =IF(ROWS($1:15)<=Nper,ROWS($1:15),"") -> 15 | C27: =IF($B27="","",IF($E$7="Weekly",Start_Date+7*(ROWS($1:15)-1),EDATE(Start_Date,VLOOKUP(IF(ASTemp!$E$7="","Monthly",ASTemp!$E$7),Parameters!$B$3:$D$6,3,0)*(ROWS($1:15)-1)))) -> 42375 | D27: =IF($B27="","",YEAR(C27)) -> 2016 | E27: =IF($B27="","",VLOOKUP(MONTH(C27),Parameters!$F$2:$G$13,2,0)) -> Jan | F27: =IF($B27="","",PV-N(J26)) -> 367833.2 | G27: =IF($B27="","",PMT(Rate,Nper,-PV,,Type)) -> 9862.3934 | H27: =IF($B27="","",PPMT(Rate,ROWS($1:15),Nper,-PV,,Type)) -> 9508.7077 | I27: =IF($B27="","",IPMT(Rate,ROWS($1:15),Nper,-PV,,Type)) -> 353.68577 | J27: =IF($B27="","",N(J26)+N(H27)) -> 141675.5 | K27: =IF($B27="","",N(K26)+N(I27)) -> 6260.3972 | L27: =IF($B27="","",PV-J27) -> 358324.5 | M27: =IF($B27="","",J27/PV) -> 0.28335101 | N27: =IF($B27="","",1-M27) -> 0.71664899
B28: =IF(ROWS($1:16)<=Nper,ROWS($1:16),"") -> 16 | C28: =IF($B28="","",IF($E$7="Weekly",Start_Date+7*(ROWS($1:16)-1),EDATE(Start_Date,VLOOKUP(IF(ASTemp!$E$7="","Monthly",ASTemp!$E$7),Parameters!$B$3:$D$6,3,0)*(ROWS($1:16)-1)))) -> 42382 | D28: =IF($B28="","",YEAR(C28)) -> 2016 | E28: =IF($B28="","",VLOOKUP(MONTH(C28),Parameters!$F$2:$G$13,2,0)) -> Jan | F28: =IF($B28="","",PV-N(J27)) -> 358324.5 | G28: =IF($B28="","",PMT(Rate,Nper,-PV,,Type)) -> 9862.3934 | H28: =IF($B28="","",PPMT(Rate,ROWS($1:16),Nper,-PV,,Type)) -> 9517.8506 | I28: =IF($B28="","",IPMT(Rate,ROWS($1:16),Nper,-PV,,Type)) -> 344.54278 | J28: =IF($B28="","",N(J27)+N(H28)) -> 151193.35 | K28: =IF($B28="","",N(K27)+N(I28)) -> 6604.94 | L28: =IF($B28="","",PV-J28) -> 348806.65 | M28: =IF($B28="","",J28/PV) -> 0.30238671 | N28: =IF($B28="","",1-M28) -> 0.69761329
B29: =IF(ROWS($1:17)<=Nper,ROWS($1:17),"") -> 17 | C29: =IF($B29="","",IF($E$7="Weekly",Start_Date+7*(ROWS($1:17)-1),EDATE(Start_Date,VLOOKUP(IF(ASTemp!$E$7="","Monthly",ASTemp!$E$7),Parameters!$B$3:$D$6,3,0)*(ROWS($1:17)-1)))) -> 42389 | D29: =IF($B29="","",YEAR(C29)) -> 2016 | E29: =IF($B29="","",VLOOKUP(MONTH(C29),Parameters!$F$2:$G$13,2,0)) -> Jan | F29: =IF($B29="","",PV-N(J28)) -> 348806.65 | G29: =IF($B29="","",PMT(Rate,Nper,-PV,,Type)) -> 9862.3934 | H29: =IF($B29="","",PPMT(Rate,ROWS($1:17),Nper,-PV,,Type)) -> 9527.0024 | I29: =IF($B29="","",IPMT(Rate,ROWS($1:17),Nper,-PV,,Type)) -> 335.391 | J29: =IF($B29="","",N(J28)+N(H29)) -> 160720.36 | K29: =IF($B29="","",N(K28)+N(I29)) -> 6940.331 | L29: =IF($B29="","",PV-J29) -> 339279.64 | M29: =IF($B29="","",J29/PV) -> 0.32144071 | N29: =IF($B29="","",1-M29) -> 0.67855929
B30: =IF(ROWS($1:18)<=Nper,ROWS($1:18),"") -> 18 | C30: =IF($B30="","",IF($E$7="Weekly",Start_Date+7*(ROWS($1:18)-1),EDATE(Start_Date,VLOOKUP(IF(ASTemp!$E$7="","Monthly",ASTemp!$E$7),Parameters!$B$3:$D$6,3,0)*(ROWS($1:18)-1)))) -> 42396 | D30: =IF($B30="","",YEAR(C30)) -> 2016 | E30: =IF($B30="","",VLOOKUP(MONTH(C30),Parameters!$F$2:$G$13,2,0)) -> Jan | F30: =IF($B30="","",PV-N(J29)) -> 339279.64 | G30: =IF($B30="","",PMT(Rate,Nper,-PV,,Type)) -> 9862.3934 | H30: =IF($B30="","",PPMT(Rate,ROWS($1:18),Nper,-PV,,Type)) -> 9536.163 | I30: =IF($B30="","",IPMT(Rate,ROWS($1:18),Nper,-PV,,Type)) -> 326.23043 | J30: =IF($B30="","",N(J29)+N(H30)) -> 170256.52 | K30: =IF($B30="","",N(K29)+N(I30)) -> 7266.5615 | L30: =IF($B30="","",PV-J30) -> 329743.48 | M30: =IF($B30="","",J30/PV) -> 0.34051304 | N30: =IF($B30="","",1-M30) -> 0.65948696
B31: =IF(ROWS($1:19)<=Nper,ROWS($1:19),"") -> 19 | C31: =IF($B31="","",IF($E$7="Weekly",Start_Date+7*(ROWS($1:19)-1),EDATE(Start_Date,VLOOKUP(IF(ASTemp!$E$7="","Monthly",ASTemp!$E$7),Parameters!$B$3:$D$6,3,0)*(ROWS($1:19)-1)))) -> 42403 | D31: =IF($B31="","",YEAR(C31)) -> 2016 | E31: =IF($B31="","",VLOOKUP(MONTH(C31),Parameters!$F$2:$G$13,2,0)) -> Feb | F31: =IF($B31="","",PV-N(J30)) -> 329743.48 | G31: =IF($B31="","",PMT(Rate,Nper,-PV,,Type)) -> 9862.3934 | H31: =IF($B31="","",PPMT(Rate,ROWS($1:19),Nper,-PV,,Type)) -> 9545.3324 | I31: =IF($B31="","",IPMT(Rate,ROWS($1:19),Nper,-PV,,Type)) -> 317.06104 | J31: =IF($B31="","",N(J30)+N(H31)) -> 179801.85 | K31: =IF($B31="","",N(K30)+N(I31)) -> 7583.6225 | L31: =IF($B31="","",PV-J31) -> 320198.15 | M31: =IF($B31="","",J31/PV) -> 0.35960371 | N31: =IF($B31="","",1-M31) -> 0.64039629
B32: =IF(ROWS($1:20)<=Nper,ROWS($1:20),"") -> 20 | C32: =IF($B32="","",IF($E$7="Weekly",Start_Date+7*(ROWS($1:20)-1),EDATE(Start_Date,VLOOKUP(IF(ASTemp!$E$7="","Monthly",ASTemp!$E$7),Parameters!$B$3:$D$6,3,0)*(ROWS($1:20)-1)))) -> 42410 | D32: =IF($B32="","",YEAR(C32)) -> 2016 | E32: =IF($B32="","",VLOOKUP(MONTH(C32),Parameters!$F$2:$G$13,2,0)) -> Feb | F32: =IF($B32="","",PV-N(J31)) -> 320198.15 | G32: =IF($B32="","",PMT(Rate,Nper,-PV,,Type)) -> 9862.3934 | H32: =IF($B32="","",PPMT(Rate,ROWS($1:20),Nper,-PV,,Type)) -> 9554.5106 | I32: =IF($B32="","",IPMT(Rate,ROWS($1:20),Nper,-PV,,Type)) -> 307.88283 | J32: =IF($B32="","",N(J31)+N(H32)) -> 189356.36 | K32: =IF($B32="","",N(K31)+N(I32)) -> 7891.5053 | L32: =IF($B32="","",PV-J32) -> 310643.64 | M32: =IF($B32="","",J32/PV) -> 0.37871273 | N32: =IF($B32="","",1-M32) -> 0.62128727
B33: =IF(ROWS($1:21)<=Nper,ROWS($1:21),"") -> 21 | C33: =IF($B33="","",IF($E$7="Weekly",Start_Date+7*(ROWS($1:21)-1),EDATE(Start_Date,VLOOKUP(IF(ASTemp!$E$7="","Monthly",ASTemp!$E$7),Parameters!$B$3:$D$6,3,0)*(ROWS($1:21)-1)))) -> 42417 | D33: =IF($B33="","",YEAR(C33)) -> 2016 | E33: =IF($B33="","",VLOOKUP(MONTH(C33),Parameters!$F$2:$G$13,2,0)) -> Feb | F33: =IF($B33="","",PV-N(J32)) -> 310643.64 | G33: =IF($B33="","",PMT(Rate,Nper,-PV,,Type)) -> 9862.3934 | H33: =IF($B33="","",PPMT(Rate,ROWS($1:21),Nper,-PV,,Type)) -> 9563.6976 | I33: =IF($B33="","",IPMT(Rate,ROWS($1:21),Nper,-PV,,Type)) -> 298.6958 | J33: =IF($B33="","",N(J32)+N(H33)) -> 198920.06 | K33: =IF($B33="","",N(K32)+N(I33)) -> 8190.2011 | L33: =IF($B33="","",PV-J33) -> 301079.94 | M33: =IF($B33="","",J33/PV) -> 0.39784012 | N33: =IF($B33="","",1-M33) -> 0.60215988
B34: =IF(ROWS($1:22)<=Nper,ROWS($1:22),"") -> 22 | C34: =IF($B34="","",IF($E$7="Weekly",Start_Date+7*(ROWS($1:22)-1),EDATE(Start_Date,VLOOKUP(IF(ASTemp!$E$7="","Monthly",ASTemp!$E$7),Parameters!$B$3:$D$6,3,0)*(ROWS($1:22)-1)))) -> 42424 | D34: =IF($B34="","",YEAR(C34)) -> 2016 | E34: =IF($B34="","",VLOOKUP(MONTH(C34),Parameters!$F$2:$G$13,2,0)) -> Feb | F34: =IF($B34="","",PV-N(J33)) -> 301079.94 | G34: =IF($B34="","",PMT(Rate,Nper,-PV,,Type)) -> 9862.3934 | H34: =IF($B34="","",PPMT(Rate,ROWS($1:22),Nper,-PV,,Type)) -> 9572.8935 | I34: =IF($B34="","",IPMT(Rate,ROWS($1:22),Nper,-PV,,Type)) -> 289.49994 | J34: =IF($B34="","",N(J33)+N(H34)) -> 208492.95 | K34: =IF($B34="","",N(K33)+N(I34)) -> 8479.7011 | L34: =IF($B34="","",PV-J34) -> 291507.05 | M34: =IF($B34="","",J34/PV) -> 0.41698591 | N34: =IF($B34="","",1-M34) -> 0.58301409
B35: =IF(ROWS($1:23)<=Nper,ROWS($1:23),"") -> 23 | C35: =IF($B35="","",IF($E$7="Weekly",Start_Date+7*(ROWS($1:23)-1),EDATE(Start_Date,VLOOKUP(IF(ASTemp!$E$7="","Monthly",ASTemp!$E$7),Parameters!$B$3:$D$6,3,0)*(ROWS($1:23)-1)))) -> 42431 | D35: =IF($B35="","",YEAR(C35)) -> 2016 | E35: =IF($B35="","",VLOOKUP(MONTH(C35),Parameters!$F$2:$G$13,2,0)) -> Mar | F35: =IF($B35="","",PV-N(J34)) -> 291507.05 | G35: =IF($B35="","",PMT(Rate,Nper,-PV,,Type)) -> 9862.3934 | H35: =IF($B35="","",PPMT(Rate,ROWS($1:23),Nper,-PV,,Type)) -> 9582.0982 | I35: =IF($B35="","",IPMT(Rate,ROWS($1:23),Nper,-PV,,Type)) -> 280.29524 | J35: =IF($B35="","",N(J34)+N(H35)) -> 218075.05 | K35: =IF($B35="","",N(K34)+N(I35)) -> 8759.9963 | L35: =IF($B35="","",PV-J35) -> 281924.95 | M35: =IF($B35="","",J35/PV) -> 0.43615011 | N35: =IF($B35="","",1-M35) -> 0.56384989
B36: =IF(ROWS($1:24)<=Nper,ROWS($1:24),"") -> 24 | C36: =IF($B36="","",IF($E$7="Weekly",Start_Date+7*(ROWS($1:24)-1),EDATE(Start_Date,VLOOKUP(IF(ASTemp!$E$7="","Monthly",ASTemp!$E$7),Parameters!$B$3:$D$6,3,0)*(ROWS($1:24)-1)))) -> 42438 | D36: =IF($B36="","",YEAR(C36)) -> 2016 | E36: =IF($B36="","",VLOOKUP(MONTH(C36),Parameters!$F$2:$G$13,2,0)) -> Mar | F36: =IF($B36="","",PV-N(J35)) -> 281924.95 | G36: =IF($B36="","",PMT(Rate,Nper,-PV,,Type)) -> 9862.3934 | H36: =IF($B36="","",PPMT(Rate,ROWS($1:24),Nper,-PV,,Type)) -> 9591.3118 | I36: =IF($B36="","",IPMT(Rate,ROWS($1:24),Nper,-PV,,Type)) -> 271.08168 | J36: =IF($B36="","",N(J35)+N(H36)) -> 227666.36 | K36: =IF($B36="","",N(K35)+N(I36)) -> 9031.078 | L36: =IF($B36="","",PV-J36) -> 272333.64 | M36: =IF($B36="","",J36/PV) -> 0.45533273 | N36: =IF($B36="","",1-M36) -> 0.54466727
B37: =IF(ROWS($1:25)<=Nper,ROWS($1:25),"") -> 25 | C37: =IF($B37="","",IF($E$7="Weekly",Start_Date+7*(ROWS($1:25)-1),EDATE(Start_Date,VLOOKUP(IF(ASTemp!$E$7="","Monthly",ASTemp!$E$7),Parameters!$B$3:$D$6,3,0)*(ROWS($1:25)-1)))) -> 42445 | D37: =IF($B37="","",YEAR(C37)) -> 2016 | E37: =IF($B37="","",VLOOKUP(MONTH(C37),Parameters!$F$2:$G$13,2,0)) -> Mar | F37: =IF($B37="","",PV-N(J36)) -> 272333.64 | G37: =IF($B37="","",PMT(Rate,Nper,-PV,,Type)) -> 9862.3934 | H37: =IF($B37="","",PPMT(Rate,ROWS($1:25),Nper,-PV,,Type)) -> 9600.5342 | I37: =IF($B37="","",IPMT(Rate,ROWS($1:25),Nper,-PV,,Type)) -> 261.85927 | J37: =IF($B37="","",N(J36)+N(H37)) -> 237266.9 | K37: =IF($B37="","",N(K36)+N(I37)) -> 9292.9373 | L37: =IF($B37="","",PV-J37) -> 262733.1 | M37: =IF($B37="","",J37/PV) -> 0.4745338 | N37: =IF($B37="","",1-M37) -> 0.5254662
B38: =IF(ROWS($1:26)<=Nper,ROWS($1:26),"") -> 26 | C38: =IF($B38="","",IF($E$7="Weekly",Start_Date+7*(ROWS($1:26)-1),EDATE(Start_Date,VLOOKUP(IF(ASTemp!$E$7="","Monthly",ASTemp!$E$7),Parameters!$B$3:$D$6,3,0)*(ROWS($1:26)-1)))) -> 42452 | D38: =IF($B38="","",YEAR(C38)) -> 2016 | E38: =IF($B38="","",VLOOKUP(MONTH(C38),Parameters!$F$2:$G$13,2,0)) -> Mar | F38: =IF($B38="","",PV-N(J37)) -> 262733.1 | G38: =IF($B38="","",PMT(Rate,Nper,-PV,,Type)) -> 9862.3934 | H38: =IF($B38="","",PPMT(Rate,ROWS($1:26),Nper,-PV,,Type)) -> 9609.7654 | I38: =IF($B38="","",IPMT(Rate,ROWS($1:26),Nper,-PV,,Type)) -> 252.62798 | J38: =IF($B38="","",N(J37)+N(H38)) -> 246876.66 | K38: =IF($B38="","",N(K37)+N(I38)) -> 9545.5652 | L38: =IF($B38="","",PV-J38) -> 253123.34 | M38: =IF($B38="","",J38/PV) -> 0.49375333 | N38: =IF($B38="","",1-M38) -> 0.50624667
B39: =IF(ROWS($1:27)<=Nper,ROWS($1:27),"") -> 27 | C39: =IF($B39="","",IF($E$7="Weekly",Start_Date+7*(ROWS($1:27)-1),EDATE(Start_Date,VLOOKUP(IF(ASTemp!$E$7="","Monthly",ASTemp!$E$7),Parameters!$B$3:$D$6,3,0)*(ROWS($1:27)-1)))) -> 42459 | D39: =IF($B39="","",YEAR(C39)) -> 2016 | E39: =IF($B39="","",VLOOKUP(MONTH(C39),Parameters!$F$2:$G$13,2,0)) -> Mar | F39: =IF($B39="","",PV-N(J38)) -> 253123.34 | G39: =IF($B39="","",PMT(Rate,Nper,-PV,,Type)) -> 9862.3934 | H39: =IF($B39="","",PPMT(Rate,ROWS($1:27),Nper,-PV,,Type)) -> 9619.0056 | I39: =IF($B39="","",IPMT(Rate,ROWS($1:27),Nper,-PV,,Type)) -> 243.38782 | J39: =IF($B39="","",N(J38)+N(H39)) -> 256495.67 | K39: =IF($B39="","",N(K38)+N(I39)) -> 9788.9531 | L39: =IF($B39="","",PV-J39) -> 243504.33 | M39: =IF($B39="","",J39/PV) -> 0.51299134 | N39: =IF($B39="","",1-M39) -> 0.48700866
B40: =IF(ROWS($1:28)<=Nper,ROWS($1:28),"") -> 28 | C40: =IF($B40="","",IF($E$7="Weekly",Start_Date+7*(ROWS($1:28)-1),EDATE(Start_Date,VLOOKUP(IF(ASTemp!$E$7="","Monthly",ASTemp!$E$7),Parameters!$B$3:$D$6,3,0)*(ROWS($1:28)-1)))) -> 42466 | D40: =IF($B40="","",YEAR(C40)) -> 2016 | E40: =IF($B40="","",VLOOKUP(MONTH(C40),Parameters!$F$2:$G$13,2,0)) -> Apr | F40: =IF($B40="","",PV-N(J39)) -> 243504.33 | G40: =IF($B40="","",PMT(Rate,Nper,-PV,,Type)) -> 9862.3934 | H40: =IF($B40="","",PPMT(Rate,ROWS($1:28),Nper,-PV,,Type)) -> 9628.2547 | I40: =IF($B40="","",IPMT(Rate,ROWS($1:28),Nper,-PV,,Type)) -> 234.13878 | J40: =IF($B40="","",N(J39)+N(H40)) -> 266123.92 | K40: =IF($B40="","",N(K39)+N(I40)) -> 10023.092 | L40: =IF($B40="","",PV-J40) -> 233876.08 | M40: =IF($B40="","",J40/PV) -> 0.53224785 | N40: =IF($B40="","",1-M40) -> 0.46775215
B41: =IF(ROWS($1:29)<=Nper,ROWS($1:29),"") -> 29 | C41: =IF($B41="","",IF($E$7="Weekly",Start_Date+7*(ROWS($1:29)-1),EDATE(Start_Date,VLOOKUP(IF(ASTemp!$E$7="","Monthly",ASTemp!$E$7),Parameters!$B$3:$D$6,3,0)*(ROWS($1:29)-1)))) -> 42473 | D41: =IF($B41="","",YEAR(C41)) -> 2016 | E41: =IF($B41="","",VLOOKUP(MONTH(C41),Parameters!$F$2:$G$13,2,0)) -> Apr | F41: =IF($B41="","",PV-N(J40)) -> 233876.08 | G41: =IF($B41="","",PMT(Rate,Nper,-PV,,Type)) -> 9862.3934 | H41: =IF($B41="","",PPMT(Rate,ROWS($1:29),Nper,-PV,,Type)) -> 9637.5126 | I41: =IF($B41="","",IPMT(Rate,ROWS($1:29),Nper,-PV,,Type)) -> 224.88084 | J41: =IF($B41="","",N(J40)+N(H41)) -> 275761.44 | K41: =IF($B41="","",N(K40)+N(I41)) -> 10247.973 | L41: =IF($B41="","",PV-J41) -> 224238.56 | M41: =IF($B41="","",J41/PV) -> 0.55152287 | N41: =IF($B41="","",1-M41) -> 0.44847713
B42: =IF(ROWS($1:30)<=Nper,ROWS($1:30),"") -> 30 | C42: =IF($B42="","",IF($E$7="Weekly",Start_Date+7*(ROWS($1:30)-1),EDATE(Start_Date,VLOOKUP(IF(ASTemp!$E$7="","Monthly",ASTemp!$E$7),Parameters!$B$3:$D$6,3,0)*(ROWS($1:30)-1)))) -> 42480 | D42: =IF($B42="","",YEAR(C42)) -> 2016 | E42: =IF($B42="","",VLOOKUP(MONTH(C42),Parameters!$F$2:$G$13,2,0)) -> Apr | F42: =IF($B42="","",PV-N(J41)) -> 224238.56 | G42: =IF($B42="","",PMT(Rate,Nper,-PV,,Type)) -> 9862.3934 | H42: =IF($B42="","",PPMT(Rate,ROWS($1:30),Nper,-PV,,Type)) -> 9646.7794 | I42: =IF($B42="","",IPMT(Rate,ROWS($1:30),Nper,-PV,,Type)) -> 215.614 | J42: =IF($B42="","",N(J41)+N(H42)) -> 285408.22 | K42: =IF($B42="","",N(K41)+N(I42)) -> 10463.587 | L42: =IF($B42="","",PV-J42) -> 214591.78 | M42: =IF($B42="","",J42/PV) -> 0.57081643 | N42: =IF($B42="","",1-M42) -> 0.42918357
...

Sheet Parameters
A2: Weeks | B2: Weekly | C2: 52 | F2: 1 | G2: Jan | H2: 1 | J2: Start / End | K2: 2
A3: Months | B3: Monthly | C3: 12 | D3: 1 | F3: 2 | G3: Feb | H3: 2 | J3: Rate | K3: =(ASTemp!$E$5*VLOOKUP(IF(ASTemp!$F$5="","Yearly",ASTemp!$F$5),Parameters!$B$2:$C$6,2,0))/VLOOKUP(IF(ASTemp!$E$7="","Monthly",ASTemp!$E$7),$B$2:$C$6,2,0) -> 0.00096153846
A4: Quarters | B4: Quarterly | C4: 4 | D4: 3 | F4: 3 | G4: Mar | H4: 3 | J4: Nper | K4: =ASTemp!$E$6*VLOOKUP(IF(ASTemp!$E$7="","Monthly",ASTemp!$E$7),$B$2:$C$6,2,0)/VLOOKUP(IF(ASTemp!$F$6="","Years",ASTemp!$F$6),Parameters!$A$2:$C$6,3,0) -> 52
A5: Half Years | B5: Six Monthly | C5: 2 | D5: 6 | F5: 4 | G5: Apr | H5: 4 | J5: Type | K5: =IF($K$2=1,1,0) -> 0
A6: Years | B6: Yearly | C6: 1 | D6: 12 | F6: 5 | G6: May | H6: 5 | J6: Start Date | K6: =IF(K5=0,EOMONTH(DATE(IF(ASTemp!$E$8="",YEAR(TODAY()),ASTemp!$E$8),IF(ASTemp!$F$8="",MONTH(TODAY()),VLOOKUP(ASTemp!$F$8,$G$2:$GT$13,2,0)),1),0),DATE(IF(ASTemp!$E$8="",YEAR(TODAY()),ASTemp!$E$8),IF(ASTemp!$F$8="",MONTH(TODAY()),VLOOKUP(ASTemp!$F$8,$G$2:$GT$13,2,0)),1)) -> 42277
F7: 6 | G7: Jun | H7: 6 | J7: Decimal Formatting | K7: =CHOOSE(ASTemp!$E$9+1,"0","0.0","0.00") -> 0.0
F8: 7 | G8: Jul | H8: 7 | J8: % Formatting | K8: =CHOOSE(ASTemp!$E$9+1,"0%","0.0%","0.00%") -> 0.0%
F9: 8 | G9: Aug | H9: 8
F10: 9 | G10: Sep | H10: 9
F11: 10 | G11: Oct | H11: 10
F12: 11 | G12: Nov | H12: 11
F13: 12 | G13: Dec | H13: 12
